<?xml version="1.0"?>
<robot xmlns:xacro="http://ros.org/wiki/xacro">

<!--
  Author: Vladislav Antipov <github: @TexnoMann>
  Contributers:
-->

  <xacro:macro name="tinybot_urdf" params="prefix
    joint1_lower_limit:=${-pi}  joint1_upper_limit:=${pi}
    joint2_lower_limit:=${-pi}  joint2_upper_limit:=${pi}
    joint3_lower_limit:=${-pi}  joint3_upper_limit:=${pi}
    joint4_lower_limit:=${-pi}  joint4_upper_limit:=${pi}
    joint5_lower_limit:=${-pi}  joint5_upper_limit:=${pi}">

    <material name="Black">
      <color rgba="0.0 0.0 0.0 1.0"/>
    </material>

    <material name="Red">
      <color rgba="0.8 0.0 0.0 1.0"/>
    </material>

    <material name="White">
      <color rgba="1.0 1.0 1.0 1.0"/>
    </material>

    <material name="Silver">
      <color rgba="0.753 0.753 0.753 1.0"/>
    </material>

    <!-- Base link -->
    <link
    name="${prefix}base_link">
    <inertial>
      <origin
        xyz="1.8574E-07 9.9166E-05 0.040638"
        rpy="0 0 0" />
      <mass
        value="1.999" />
      <inertia
        ixx="0.00069146"
        ixy="8.8315E-09"
        ixz="-4.3606E-10"
        iyy="0.00070155"
        iyz="4.9309E-07"
        izz="0.0012677" />
    </inertial>
    <visual>
      <origin
        xyz="0 0 0"
        rpy="0 0 0" />
      <geometry>
        <mesh
          filename="package://tinybot_description/meshes/base_link.STL" />
      </geometry>
      <material
        name="">
        <color
          rgba="0.6902 0.6902 0.6902 1" />
      </material>
    </visual>
    <collision>
      <origin
        xyz="0 0 0"
        rpy="0 0 0" />
      <geometry>
        <mesh
          filename="package://tinybot_description/meshes/base_link.STL" />
      </geometry>
    </collision>
  </link>
  <link
    name="${prefix}link1">
    <inertial>
      <origin
        xyz="0.00053822 -0.0030286 0.057419"
        rpy="0 0 0" />
      <mass
        value="1.962" />
      <inertia
        ixx="0.00020802"
        ixy="5.8641E-07"
        ixz="-8.8309E-09"
        iyy="0.00033929"
        iyz="-4.3611E-10"
        izz="0.00021938" />
    </inertial>
    <visual>
      <origin
        xyz="0 0 0"
        rpy="0 0 0" />
      <geometry>
        <mesh
          filename="package://tinybot_description/meshes/link1.STL" />
      </geometry>
      <material
        name="">
        <color
          rgba="0.52941 0.54902 0.54902 1" />
      </material>
    </visual>
    <collision>
      <origin
        xyz="0 0 0"
        rpy="0 0 0" />
      <geometry>
        <mesh
          filename="package://tinybot_description/meshes/link1.STL" />
      </geometry>
    </collision>
  </link>
  <joint
    name="joint1"
    type="revolute">
    <origin
      xyz="0 0 0.1015"
      rpy="0 0 0" />
    <parent
      link="base_link" />
    <child
      link="link1" />
    <axis
      xyz="0 0 1" />
    <limit
        lower="${joint1_lower_limit}"
        upper="${joint1_upper_limit}"
        effort="50"
        velocity="1.0" />
      <dynamics
        damping="5"
        friction="1" />
  </joint>
  <link
    name="link2">
    <inertial>
      <origin
        xyz="0.12597 8.5763E-10 0.024345"
        rpy="0 0 0" />
      <mass
        value="0.778" />
      <inertia
        ixx="0.00012535"
        ixy="1.2464E-11"
        ixz="1.3405E-10"
        iyy="0.0013458"
        iyz="1.6238E-10"
        izz="0.001368" />
    </inertial>
    <visual>
      <origin
        xyz="0 0 0"
        rpy="0 0 0" />
      <geometry>
        <mesh
          filename="package://tinybot_description/meshes/link2.STL" />
      </geometry>
      <material
        name="">
        <color
          rgba="1 1 1 1" />
      </material>
    </visual>
    <collision>
      <origin
        xyz="0 0 0"
        rpy="0 0 0" />
      <geometry>
        <mesh
          filename="package://tinybot_description/meshes/link2.STL" />
      </geometry>
    </collision>
  </link>
  <joint
    name="${prefix}joint2"
    type="revolute">
    <origin
      xyz="0 -0.032 0.068"
      rpy="1.5708 -1.5708 0" />
    <parent
      link="${prefix}link1" />
    <child
      link="${prefix}link2" />
    <axis
      xyz="0 0 1" />
    <limit
        lower="${joint2_lower_limit}"
        upper="${joint2_upper_limit}"
        effort="50"
        velocity="1.0" />
      <dynamics
        damping="5"
        friction="1" />
  </joint>
  <link
    name="${prefix}link3">
    <inertial>
      <origin
        xyz="0.16701 -0.00035709 -0.024615"
        rpy="0 0 0" />
      <mass
        value="2.849" />
      <inertia
        ixx="0.00033763"
        ixy="-1.9393E-10"
        ixz="1.2229E-09"
        iyy="0.00073725"
        iyz="2.8549E-06"
        izz="0.00082439" />
    </inertial>
    <visual>
      <origin
        xyz="0 0 0"
        rpy="0 0 0" />
      <geometry>
        <mesh
          filename="package://tinybot_description/meshes/link3.STL" />
      </geometry>
      <material
        name="">
        <color
          rgba="0.8 0.8 0.8 1" />
      </material>
    </visual>
    <collision>
      <origin
        xyz="0 0 0"
        rpy="0 0 0" />
      <geometry>
        <mesh
          filename="package://tinybot_description/meshes/link3.STL" />
      </geometry>
    </collision>
  </link>
  <joint
    name="${prefix}joint3"
    type="revolute">
    <origin
      xyz="0.24998 0 0"
      rpy="0 0 0" />
    <parent
      link="${prefix}link2" />
    <child
      link="${prefix}link3" />
    <axis
      xyz="0 0 1" />
    <limit
        lower="${joint3_lower_limit}"
        upper="${joint3_upper_limit}"
        effort="25"
        velocity="1.0" />
      <dynamics
        damping="5"
        friction="1" />
  </joint>
  <link
    name="${prefix}link4">
    <inertial>
      <origin
        xyz="0.10073 5.7206E-05 0.027691"
        rpy="0 0 0" />
      <mass
        value="1.195" />
      <inertia
        ixx="0.00025267"
        ixy="4.2615E-07"
        ixz="2.4602E-07"
        iyy="0.00027086"
        iyz="3.6039E-07"
        izz="0.00028737" />
    </inertial>
    <visual>
      <origin
        xyz="0 0 0"
        rpy="0 0 0" />
      <geometry>
        <mesh
          filename="package://tinybot_description/meshes/link4.STL" />
      </geometry>
      <material
        name="">
        <color
          rgba="0.52941 0.54902 0.54902 1" />
      </material>
    </visual>
    <collision>
      <origin
        xyz="0 0 0"
        rpy="0 0 0" />
      <geometry>
        <mesh
          filename="package://tinybot_description/meshes/link4.STL" />
      </geometry>
    </collision>
  </link>
  <joint
    name="${prefix}joint4"
    type="revolute">
    <origin
      xyz="0.33402 0 0"
      rpy="0 0 0" />
    <parent
      link="${prefix}link3" />
    <child
      link="${prefix}link4" />
    <axis
      xyz="0 0 1" />
    <limit
        lower="${joint4_lower_limit}"
        upper="${joint4_upper_limit}"
        effort="15"
        velocity="1.0" />
      <dynamics
        damping="5"
        friction="1" />
  </joint>

  <link
    name="${prefix}link5">
    <inertial>
      <origin
        xyz="0.0 0.0 0.01"
        rpy="0 0 0" />
      <mass
        value="0.2" />
      <inertia
        ixx="0.00025267"
        ixy="4.2615E-07"
        ixz="2.4602E-07"
        iyy="0.0"
        iyz="3.6039E-07"
        izz="0.00028737" />
    </inertial>
  </link>
  <joint
    name="${prefix}joint5"
    type="revolute">
    <origin
      xyz="0.167 0 0.029"
      rpy="0 ${0.5*pi} 0" />
    <parent
      link="${prefix}link4" />
    <child
      link="${prefix}link5" />
    <axis
      xyz="0 0 1" />
    <limit
        lower="${joint5_lower_limit}"
        upper="${joint5_upper_limit}"
        effort="15"
        velocity="1.0" />
      <dynamics
        damping="5"
        friction="1" />
  </joint>
  
  </xacro:macro>
</robot>